<?xml version="1.0" ?>
<!-- =================================================================================== -->
<!-- |    This document was autogenerated by xacro from src/urdf_simulate/urdf/robot.xacro | -->
<!-- |    EDITING THIS FILE BY HAND IS NOT RECOMMENDED                                 | -->
<!-- =================================================================================== -->
<robot name="robot">
  <!-- 1 cm -->
  <!-- 2 cm -->
  <!-- 15.2 cm -->
  <!-- 30 cm -->
  <!-- <xacro:property name="telescopic_rod_radius" value="0.03" /> -->
  <!-- 20 cm -->
  <!-- Base Link -->
  <link name="base_link">
    <!-- <visual>
            <geometry>
                <box size="${chassis_width} ${chassis_length} ${chassis_height}" />
            </geometry>
            <material name="gray" />
        </visual> -->
    <!-- <collision>
            <geometry>
                <box size="${chassis_width} ${chassis_length} ${chassis_height}" />
            </geometry>
        </collision> -->
    <inertial>
      <mass value="10.0"/>
      <origin xyz="0 0 0"/>
      <inertia ixx="1" ixy="0.0" ixz="0.0" iyy="1" iyz="0.0" izz="1"/>
    </inertial>
  </link>
  <!-- Four Wheels -->
  <link name="wheel_left">
    <visual>
      <geometry>
        <cylinder length="0.02" radius="0.076"/>
      </geometry>
      <material name="black"/>
    </visual>
    <collision>
      <geometry>
        <cylinder length="0.02" radius="0.076"/>
      </geometry>
    </collision>
    <inertial>
      <mass value="1.0"/>
      <origin xyz="0 0 0"/>
      <inertia ixx="0.01" ixy="0.0" ixz="0.0" iyy="0.01" iyz="0.0" izz="0.01"/>
    </inertial>
  </link>
  <link name="wheel_right">
    <visual>
      <geometry>
        <cylinder length="0.02" radius="0.076"/>
      </geometry>
      <material name="black"/>
    </visual>
    <collision>
      <geometry>
        <cylinder length="0.02" radius="0.076"/>
      </geometry>
    </collision>
    <inertial>
      <mass value="1.0"/>
      <origin xyz="0 0 0"/>
      <inertia ixx="0.01" ixy="0.0" ixz="0.0" iyy="0.01" iyz="0.0" izz="0.01"/>
    </inertial>
  </link>
  <!-- Joints for Wheels -->
  <joint name="joint_wheel_left" type="continuous">
    <parent link="base_link"/>
    <child link="wheel_left"/>
    <origin rpy="0 -1.570796326795 0" xyz="-0.2 0 -0.005"/>
    <axis xyz="0 0 1"/>
  </joint>
  <joint name="joint_wheel_right" type="continuous">
    <parent link="base_link"/>
    <child link="wheel_right"/>
    <origin rpy="0 -1.570796326795 0" xyz="0.2 0 -0.005"/>
    <axis xyz="0 0 1"/>
  </joint>
  <link name="caster_forward">
    <!-- <visual>
            <geometry>
                <sphere radius="${caster_radius}" />
            </geometry>
            <origin xyz="0 0 0" rpy="0 0 0" />
            <material name="green" />
        </visual> -->
    <collision>
      <origin rpy="0 0 0" xyz="0 0 0"/>
      <geometry>
        <sphere radius="0.03"/>
      </geometry>
    </collision>
    <!-- <inertial>
            <mass value="0.5" />
            <inertia ixx="3.000e-4" iyy="3.000e-4" izz="3.000e-4" ixy="0" ixz="0" iyz="0" />
        </inertial> -->
  </link>
  <link name="caster_backward">
    <!-- <visual>
            <geometry>
                <sphere radius="${caster_radius}" />
            </geometry>
            <origin xyz="0 0 0" rpy="0 0 0" />
            <material name="green" />
        </visual> -->
    <collision>
      <origin rpy="0 0 0" xyz="0 0 0"/>
      <geometry>
        <sphere radius="0.03"/>
      </geometry>
    </collision>
    <!-- <inertial>
            <mass value="0.5" />
            <inertia ixx="3.000e-4" iyy="3.000e-4" izz="3.000e-4" ixy="0" ixz="0" iyz="0" />
        </inertial> -->
  </link>
  <joint name="caster_forward_joint" type="fixed">
    <origin rpy="0 0 0" xyz="0 0.17 -0.051000000000000004"/>
    <parent link="base_link"/>
    <child link="caster_forward"/>
  </joint>
  <joint name="caster_backward_joint" type="fixed">
    <origin rpy="0 0 0" xyz="0 -0.17 -0.051000000000000004"/>
    <parent link="base_link"/>
    <child link="caster_backward"/>
  </joint>
  <!-- Telescopic Rod -->
  <!-- <link name="telescopic_rod">
        <visual>
            <geometry>
                <cylinder radius="${telescopic_rod_radius}" length="${max_lift_height}" />
            </geometry>
            <material name="silver" />
        </visual>
        <collision>
            <geometry>
                <cylinder radius="${telescopic_rod_radius}" length="${max_lift_height}" />
            </geometry>
        </collision>
        <inertial>
            <mass value="0.5" />
            <origin xyz="0 0 0" />
            <inertia ixx="0.001" ixy="0.0" ixz="0.0" iyy="0.001" iyz="0.0" izz="0.001" />
        </inertial>
    </link> -->
  <!-- Joint for Telescopic Rod -->
  <!-- <joint name="joint_telescopic_rod" type="fixed">
        <parent link="base_link" />
        <child link="telescopic_rod" />
        <origin xyz="0 0 ${(chassis_height+max_lift_height)/2}" />
    </joint> -->
  <!-- Body Link on Top of Telescopic Rod -->
  <link name="body_top">
    <visual>
      <geometry>
        <box size="0.4 0.4 0.2"/>
      </geometry>
      <material name="blue"/>
    </visual>
    <collision>
      <geometry>
        <box size="0.4 0.4 0.2"/>
      </geometry>
    </collision>
    <inertial>
      <mass value="0.1"/>
      <origin xyz="0 0 0"/>
      <inertia ixx="0.02" ixy="0.0" ixz="0.0" iyy="0.02" iyz="0.0" izz="0.02"/>
    </inertial>
  </link>
  <joint name="joint_body_top" type="prismatic">
    <parent link="base_link"/>
    <child link="body_top"/>
    <origin xyz="0 0 0.1"/>
    <axis xyz="0 0 1"/>
    <limit effort="1.0" lower="0.1" upper="0.3" velocity="0.1"/>
    <!-- 10 cm to 30 cm -->
  </joint>
  <link name="body_top_semantic">
    <visual>
      <geometry>
        <sphere radius="0.05"/>
      </geometry>
      <material name="black"/>
    </visual>
    <collision>
      <geometry>
        <sphere radius="0.05"/>
      </geometry>
    </collision>
  </link>
  <joint name="joint_body_top_semantic" type="fixed">
    <parent link="body_top"/>
    <child link="body_top_semantic"/>
    <origin xyz="0 0.15000000000000002 0.1"/>
  </joint>
  <!-- Transmission for the wheels -->
  <transmission name="trans_wheel_left">
    <type>transmission_interface/SimpleTransmission</type>
    <joint name="joint_wheel_left">
      <hardwareInterface>hardware_interface/VelocityJointInterface</hardwareInterface>
    </joint>
    <actuator name="actuator_wheel_left">
      <mechanicalReduction>1</mechanicalReduction>
    </actuator>
  </transmission>
  <transmission name="trans_wheel_right">
    <type>transmission_interface/SimpleTransmission</type>
    <joint name="joint_wheel_right">
      <hardwareInterface>hardware_interface/VelocityJointInterface</hardwareInterface>
    </joint>
    <actuator name="actuator_wheel_right">
      <mechanicalReduction>1</mechanicalReduction>
    </actuator>
  </transmission>
  <transmission name="trans_body_top">
    <type>transmission_interface/SimpleTransmission</type>
    <joint name="joint_body_top">
      <hardwareInterface>hardware_interface/PositionJointInterface</hardwareInterface>
    </joint>
    <actuator name="actuator_body_top">
      <mechanicalReduction>1</mechanicalReduction>
    </actuator>
  </transmission>
  <gazebo>
    <plugin filename="libgazebo_ros_control.so" name="gazebo_ros_control">
      <robotNamespace>/robot</robotNamespace>
    </plugin>
  </gazebo>
  <gazebo reference="base_link">
    <material>Gazebo/Grey</material>
  </gazebo>
  <gazebo reference="wheel_left">
    <material>Gazebo/DarkGrey</material>
  </gazebo>
  <gazebo reference="wheel_right">
    <material>Gazebo/DarkGrey</material>
  </gazebo>
  <gazebo reference="telescopic_rod">
    <material>Gazebo/White</material>
  </gazebo>
  <gazebo reference="body_top">
    <material>Gazebo/DarkYellow </material>
  </gazebo>
  <gazebo reference="body_top_semantic">
    <sensor name="head_ydlidar_sensor" type="gpu_ray">
      <pose>0 0 0 0 0 0</pose>
      <visualize>true</visualize>
      <update_rate>50</update_rate>
      <ray>
        <scan>
          <horizontal>
            <samples>700</samples>
            <resolution>1</resolution>
            <min_angle>-3.14159265359</min_angle>
            <max_angle>3.14159265359</max_angle>
          </horizontal>
        </scan>
        <range>
          <min>0.12</min>
          <max>8</max>
          <resolution>0.72</resolution>
        </range>
        <noise>
          <type>gaussian</type>
          <!-- Noise parameters based on published spec for Hokuyo laser
               achieving "+-30mm" accuracy at range < 10m.  A mean of 0.0m and
               stddev of 0.01m will put 99.7% of samples within 0.03m of the true
               reading. -->
          <mean>0.0</mean>
          <stddev>0.01</stddev>
        </noise>
      </ray>
      <plugin filename="libgazebo_ros_gpu_laser.so" name="gazebo_ros_head_ydlidar_controller">
        <robotNamespace>/robot</robotNamespace>
        <topicName>scan</topicName>
        <frameName>body_top_semantic</frameName>
      </plugin>
    </sensor>
    <material>Gazebo/FlatBlack</material>
  </gazebo>
  <gazebo reference="caster_forward">
    <mu1 value="0.0"/>
    <mu2 value="0.0"/>
  </gazebo>
  <gazebo reference="caster_backward">
    <mu1 value="0.0"/>
    <mu2 value="0.0"/>
  </gazebo>
</robot>

