<?xml version="1.0" ?>
<!-- =================================================================================== -->
<!-- |    This document was autogenerated by xacro from src/urdf_simulate/urdf/my_robot.xacro | -->
<!-- |    EDITING THIS FILE BY HAND IS NOT RECOMMENDED                                 | -->
<!-- =================================================================================== -->
<robot name="four_wheeled_robot">
  <!-- 10 cm -->
  <!-- 2 cm -->
  <!-- 2 cm -->
  <!-- 20 cm -->
  <!-- Base Link -->
  <link name="base_link">
    <visual>
      <geometry>
        <box size="0.4 0.5 0.1"/>
      </geometry>
      <material name="gray"/>
    </visual>
    <collision>
      <geometry>
        <box size="0.4 0.5 0.1"/>
      </geometry>
    </collision>
    <inertial>
      <mass value="10.0"/>
      <origin xyz="0 0 0"/>
      <inertia ixx="0.1" ixy="0.0" ixz="0.0" iyy="0.1" iyz="0.0" izz="0.1"/>
    </inertial>
  </link>
  <!-- Four Wheels -->
  <link name="wheel_fl">
    <visual>
      <geometry>
        <cylinder length="0.02" radius="0.076"/>
      </geometry>
      <material name="black"/>
    </visual>
    <collision>
      <geometry>
        <cylinder length="0.02" radius="0.076"/>
      </geometry>
    </collision>
    <inertial>
      <mass value="1.0"/>
      <origin xyz="0 0 0"/>
      <inertia ixx="0.01" ixy="0.0" ixz="0.0" iyy="0.01" iyz="0.0" izz="0.01"/>
    </inertial>
  </link>
  <link name="wheel_fr">
    <visual>
      <geometry>
        <cylinder length="0.02" radius="0.076"/>
      </geometry>
      <material name="black"/>
    </visual>
    <collision>
      <geometry>
        <cylinder length="0.02" radius="0.076"/>
      </geometry>
    </collision>
    <inertial>
      <mass value="1.0"/>
      <origin xyz="0 0 0"/>
      <inertia ixx="0.01" ixy="0.0" ixz="0.0" iyy="0.01" iyz="0.0" izz="0.01"/>
    </inertial>
  </link>
  <link name="wheel_bl">
    <visual>
      <geometry>
        <cylinder length="0.02" radius="0.076"/>
      </geometry>
      <material name="black"/>
    </visual>
    <collision>
      <geometry>
        <cylinder length="0.02" radius="0.076"/>
      </geometry>
    </collision>
    <inertial>
      <mass value="1.0"/>
      <origin xyz="0 0 0"/>
      <inertia ixx="0.01" ixy="0.0" ixz="0.0" iyy="0.01" iyz="0.0" izz="0.01"/>
    </inertial>
  </link>
  <link name="wheel_br">
    <visual>
      <geometry>
        <cylinder length="0.02" radius="0.076"/>
      </geometry>
      <material name="black"/>
    </visual>
    <collision>
      <geometry>
        <cylinder length="0.02" radius="0.076"/>
      </geometry>
    </collision>
    <inertial>
      <mass value="1.0"/>
      <origin xyz="0 0 0"/>
      <inertia ixx="0.01" ixy="0.0" ixz="0.0" iyy="0.01" iyz="0.0" izz="0.01"/>
    </inertial>
  </link>
  <!-- Joints for Wheels -->
  <joint name="joint_wheel_fl" type="continuous">
    <parent link="base_link"/>
    <child link="wheel_fl"/>
    <origin rpy="0 -1.570796326795 0" xyz="-0.2 0.174 -0.05"/>
    <!--
        Place wheel at the front-left corner -->
    <axis xyz="0 0 1"/>
  </joint>
  <joint name="joint_wheel_fr" type="continuous">
    <parent link="base_link"/>
    <child link="wheel_fr"/>
    <origin rpy="0 -1.570796326795 0" xyz="0.2 0.174 -0.05"/>
    <!--
        Place wheel at the front-right corner -->
    <axis xyz="0 0 1"/>
  </joint>
  <joint name="joint_wheel_bl" type="continuous">
    <parent link="base_link"/>
    <child link="wheel_bl"/>
    <origin rpy="0 -1.570796326795 0" xyz="-0.2 -0.174 -0.05"/>
    <!--
        Place wheel at the back-left corner -->
    <axis xyz="0 0 1"/>
  </joint>
  <joint name="joint_wheel_br" type="continuous">
    <parent link="base_link"/>
    <child link="wheel_br"/>
    <origin rpy="0 -1.570796326795 0" xyz="0.2 -0.174 -0.05"/>
    <!-- Place wheel at the back-right corner -->
    <axis xyz="0 0 1"/>
  </joint>
  <!-- Telescopic Rod -->
  <link name="telescopic_rod">
    <visual>
      <geometry>
        <cylinder length="0.3" radius="0.02"/>
      </geometry>
      <material name="silver"/>
    </visual>
    <collision>
      <geometry>
        <cylinder length="0.3" radius="0.02"/>
      </geometry>
    </collision>
    <inertial>
      <mass value="0.5"/>
      <origin xyz="0 0 0"/>
      <inertia ixx="0.001" ixy="0.0" ixz="0.0" iyy="0.001" iyz="0.0" izz="0.001"/>
    </inertial>
  </link>
  <!-- Joint for Telescopic Rod -->
  <joint name="joint_telescopic_rod" type="fixed">
    <parent link="base_link"/>
    <child link="telescopic_rod"/>
    <origin xyz="0 0 0.2"/>
    <!-- Attach rod to the top of the base -->
  </joint>
  <!-- Body Link on Top of Telescopic Rod -->
  <link name="body_top">
    <visual>
      <geometry>
        <box size="0.4 0.5 0.2"/>
      </geometry>
      <material name="blue"/>
    </visual>
    <collision>
      <geometry>
        <box size="0.4 0.5 0.2"/>
      </geometry>
    </collision>
    <inertial>
      <mass value="2.0"/>
      <origin xyz="0 0 0"/>
      <inertia ixx="0.02" ixy="0.0" ixz="0.0" iyy="0.02" iyz="0.0" izz="0.02"/>
    </inertial>
  </link>
  <!-- Joint for Body Top -->
  <joint name="joint_body_top" type="prismatic">
    <parent link="telescopic_rod"/>
    <child link="body_top"/>
    <origin xyz="0 0 0.05000000000000002"/>
    <!-- Attach body to
        the top of the rod -->
    <axis xyz="0 0 1"/>
    <limit effort="10.0" lower="0" upper="0.19999999999999998" velocity="0.05"/>
    <!-- 10 cm to 30 cm -->
  </joint>
  <!-- Transmission for the wheels -->
  <transmission name="trans_wheel_fl">
    <type>transmission_interface/SimpleTransmission</type>
    <joint name="joint_wheel_fl">
      <hardwareInterface>hardware_interface/VelocityJointInterface</hardwareInterface>
    </joint>
    <actuator name="actuator_wheel_fl">
      <mechanicalReduction>1</mechanicalReduction>
    </actuator>
  </transmission>
  <transmission name="trans_wheel_fr">
    <type>transmission_interface/SimpleTransmission</type>
    <joint name="joint_wheel_fr">
      <hardwareInterface>hardware_interface/VelocityJointInterface</hardwareInterface>
    </joint>
    <actuator name="actuator_wheel_fr">
      <mechanicalReduction>1</mechanicalReduction>
    </actuator>
  </transmission>
  <transmission name="trans_wheel_bl">
    <type>transmission_interface/SimpleTransmission</type>
    <joint name="joint_wheel_bl">
      <hardwareInterface>hardware_interface/VelocityJointInterface</hardwareInterface>
    </joint>
    <actuator name="actuator_wheel_bl">
      <mechanicalReduction>1</mechanicalReduction>
    </actuator>
  </transmission>
  <transmission name="trans_wheel_br">
    <type>transmission_interface/SimpleTransmission</type>
    <joint name="joint_wheel_br">
      <hardwareInterface>hardware_interface/VelocityJointInterface</hardwareInterface>
    </joint>
    <actuator name="actuator_wheel_br">
      <mechanicalReduction>1</mechanicalReduction>
    </actuator>
  </transmission>
  <!-- Gazebo plugin for differential drive control -->
  <gazebo>
    <plugin filename="libgazebo_ros_diff_drive.so" name="gazebo_ros_diff_drive">
      <ros>
        <namespace>/my_robot</namespace>
        <remapping>cmd_vel:=cmd_vel</remapping>
      </ros>
      <updateRate>50</updateRate>
      <leftJoint>joint_wheel_bl</leftJoint>
      <leftJoint>joint_wheel_fl</leftJoint>
      <rightJoint>joint_wheel_br</rightJoint>
      <rightJoint>joint_wheel_fr</rightJoint>
      <wheelSeparation>0.4</wheelSeparation>
      <wheelDiameter>0.152</wheelDiameter>
      <torque>0.5</torque>
    </plugin>
  </gazebo>
</robot>

