<?xml version="1.0" ?>
<!-- =================================================================================== -->
<!-- |    This document was autogenerated by xacro from src/urdf_simulate/urdf/my_robot.xacro | -->
<!-- |    EDITING THIS FILE BY HAND IS NOT RECOMMENDED                                 | -->
<!-- =================================================================================== -->
<robot name="four_wheeled_robot">
  <!-- 10 cm -->
  <!-- 2 cm -->
  <!-- 15.2 cm -->
  <!-- 2 cm -->
  <!-- 20 cm -->
  <link name="base_footprint">
    <visual>
      <geometry>
        <sphere radius="0.001"/>
      </geometry>
    </visual>
  </link>
  <joint name="base_link_footprint" type="fixed">
    <parent link="base_footprint"/>
    <child link="base_link"/>
    <origin xyz="0 0 0.081"/>
  </joint>
  <!-- Base Link -->
  <link name="base_link">
    <visual>
      <geometry>
        <box size="0.4 0.1 0.01"/>
      </geometry>
      <material name="gray"/>
    </visual>
    <collision>
      <geometry>
        <box size="0.4 0.1 0.01"/>
      </geometry>
    </collision>
    <inertial>
      <mass value="10.0"/>
      <origin xyz="0 0 0"/>
      <inertia ixx="0.1" ixy="0.0" ixz="0.0" iyy="0.1" iyz="0.0" izz="0.1"/>
    </inertial>
  </link>
  <!-- Four Wheels -->
  <link name="wheel_left">
    <visual>
      <geometry>
        <cylinder length="0.02" radius="0.076"/>
      </geometry>
      <material name="black"/>
    </visual>
    <collision>
      <geometry>
        <cylinder length="0.02" radius="0.076"/>
      </geometry>
    </collision>
    <inertial>
      <mass value="1.0"/>
      <origin xyz="0 0 0"/>
      <inertia ixx="0.01" ixy="0.0" ixz="0.0" iyy="0.01" iyz="0.0" izz="0.01"/>
    </inertial>
  </link>
  <link name="wheel_right">
    <visual>
      <geometry>
        <cylinder length="0.02" radius="0.076"/>
      </geometry>
      <material name="black"/>
    </visual>
    <collision>
      <geometry>
        <cylinder length="0.02" radius="0.076"/>
      </geometry>
    </collision>
    <inertial>
      <mass value="1.0"/>
      <origin xyz="0 0 0"/>
      <inertia ixx="0.01" ixy="0.0" ixz="0.0" iyy="0.01" iyz="0.0" izz="0.01"/>
    </inertial>
  </link>
  <!-- Joints for Wheels -->
  <joint name="joint_wheel_left" type="continuous">
    <parent link="base_link"/>
    <child link="wheel_left"/>
    <origin rpy="0 -1.570796326795 0" xyz="-0.2 0 -0.005"/>
    <axis xyz="0 0 1"/>
  </joint>
  <joint name="joint_wheel_right" type="continuous">
    <parent link="base_link"/>
    <child link="wheel_right"/>
    <origin rpy="0 -1.570796326795 0" xyz="0.2 0 -0.005"/>
    <axis xyz="0 0 1"/>
  </joint>
  <link name="caster_forward">
    <visual>
      <geometry>
        <sphere radius="0.03"/>
      </geometry>
      <origin rpy="0 0 0" xyz="0 0 0"/>
      <material name="green"/>
    </visual>
    <collision>
      <origin rpy="0 0 0" xyz="0 0 0"/>
      <geometry>
        <sphere radius="0.03"/>
      </geometry>
    </collision>
    <!-- <inertial>
            <mass value="0.5" />
            <inertia ixx="3.000e-4" iyy="3.000e-4" izz="3.000e-4" ixy="0" ixz="0" iyz="0" />
        </inertial> -->
  </link>
  <link name="caster_backward">
    <visual>
      <geometry>
        <sphere radius="0.03"/>
      </geometry>
      <origin rpy="0 0 0" xyz="0 0 0"/>
      <material name="green"/>
    </visual>
    <collision>
      <origin rpy="0 0 0" xyz="0 0 0"/>
      <geometry>
        <sphere radius="0.03"/>
      </geometry>
    </collision>
    <!-- <inertial>
            <mass value="0.5" />
            <inertia ixx="3.000e-4" iyy="3.000e-4" izz="3.000e-4" ixy="0" ixz="0" iyz="0" />
        </inertial> -->
  </link>
  <joint name="caster_forward_joint" type="fixed">
    <origin rpy="0 0 0" xyz="0 0.020000000000000004 -0.05"/>
    <parent link="base_link"/>
    <child link="caster_forward"/>
  </joint>
  <joint name="caster_backward_joint" type="fixed">
    <origin rpy="0 0 0" xyz="0 -0.020000000000000004 -0.05"/>
    <parent link="base_link"/>
    <child link="caster_backward"/>
  </joint>
  <!-- Telescopic Rod -->
  <link name="telescopic_rod">
    <visual>
      <geometry>
        <cylinder length="0.3" radius="0.03"/>
      </geometry>
      <material name="silver"/>
    </visual>
    <collision>
      <geometry>
        <cylinder length="0.3" radius="0.03"/>
      </geometry>
    </collision>
    <inertial>
      <mass value="0.5"/>
      <origin xyz="0 0 0"/>
      <inertia ixx="0.001" ixy="0.0" ixz="0.0" iyy="0.001" iyz="0.0" izz="0.001"/>
    </inertial>
  </link>
  <!-- Joint for Telescopic Rod -->
  <joint name="joint_telescopic_rod" type="fixed">
    <parent link="base_link"/>
    <child link="telescopic_rod"/>
    <origin xyz="0 0 0.155"/>
    <!-- Attach rod to the top of the base -->
  </joint>
  <!-- Body Link on Top of Telescopic Rod -->
  <link name="body_top">
    <visual>
      <geometry>
        <box size="0.4 0.4 0.2"/>
      </geometry>
      <material name="blue"/>
    </visual>
    <collision>
      <geometry>
        <box size="0.4 0.4 0.2"/>
      </geometry>
    </collision>
    <inertial>
      <mass value="2.0"/>
      <origin xyz="0 0 0"/>
      <inertia ixx="0.02" ixy="0.0" ixz="0.0" iyy="0.02" iyz="0.0" izz="0.02"/>
    </inertial>
  </link>
  <!-- Joint for Body Top -->
  <joint name="joint_body_top" type="prismatic">
    <parent link="telescopic_rod"/>
    <child link="body_top"/>
    <origin xyz="0 0 0.05000000000000002"/>
    <!-- Attach body to
        the top of the rod -->
    <axis xyz="0 0 1"/>
    <limit effort="10.0" lower="0" upper="0.19999999999999998" velocity="0.05"/>
    <!-- 10 cm to 30 cm -->
  </joint>
  <link name="body_top_semantic">
    <visual>
      <geometry>
        <sphere radius="0.05"/>
      </geometry>
      <material name="black"/>
    </visual>
    <collision>
      <geometry>
        <sphere radius="0.05"/>
      </geometry>
    </collision>
  </link>
  <joint name="joint_body_top_semantic" type="fixed">
    <parent link="body_top"/>
    <child link="body_top_semantic"/>
    <origin xyz="0 0.15000000000000002 0.1"/>
  </joint>
  <!-- Transmission for the wheels -->
  <transmission name="trans_wheel_left">
    <type>transmission_interface/SimpleTransmission</type>
    <joint name="joint_wheel_left">
      <hardwareInterface>hardware_interface/VelocityJointInterface</hardwareInterface>
    </joint>
    <actuator name="actuator_wheel_left">
      <mechanicalReduction>1</mechanicalReduction>
    </actuator>
  </transmission>
  <transmission name="trans_wheel_right">
    <type>transmission_interface/SimpleTransmission</type>
    <joint name="joint_wheel_right">
      <hardwareInterface>hardware_interface/VelocityJointInterface</hardwareInterface>
    </joint>
    <actuator name="actuator_wheel_right">
      <mechanicalReduction>1</mechanicalReduction>
    </actuator>
  </transmission>
  <!-- Gazebo plugin for differential drive control -->
  <gazebo>
    <plugin filename="libgazebo_ros_diff_drive.so" name="gazebo_ros_diff_drive">
      <ros>
        <namespace>/my_robot</namespace>
        <remapping>cmd_vel:=cmd_vel</remapping>
      </ros>
      <updateRate>50</updateRate>
      <leftJoint>joint_wheel_left</leftJoint>
      <rightJoint>joint_wheel_right</rightJoint>
      <wheelSeparation>0.4</wheelSeparation>
      <wheelDiameter>0.152</wheelDiameter>
      <torque>5</torque>
    </plugin>
  </gazebo>
  <gazebo reference="caster_link">
    <mu1 value="0.0"/>
    <mu2 value="0.0"/>
  </gazebo>
</robot>

